Workbook

Sheet Configurator (2)
A1: 1/8” Emitter, 954 cavity foil, standard, PVDF, 3/8” FPT, 1/8” FPT | B1: S003953105 | C1: D09530000VXE0NM | D1: 3340.5
A2: 1/8” Emitter, 953 dome foil, standard, stainless, 3/8” FPT, 1/8” FPT | B2: S00195310X | C2: D09530000VXE0TX | D2: 3215
A3: 1/4” Emitter, 953 dome foil, standard, stainless, 3/4” FPT, 1/4” FPT | B3: S002953X4F | C3: D09530002VXESDF | D3: 3215
A4: 1/4” Emitter, 953 dome foil, escutcheon, stainless, 3/4” FPT, 1/4” FPT | B4: S002953X2E | C4: D09530002VXEEDF | D4: 3215
A5: 1/4” Emitter, 954 cavity foil, standard, PVDF, 3/8” FPT, 1/8” FPT | B5: S003953170 | C5: D09530002VXCVE0 | D5: 3339
A6: 3/8” Emitter, 953 dome foil, escutcheon, stainless, 3/4” FPT, 1/4” FPT | B6: S003953032 | C6: D09530003VXE0DF | D6: 1490.5
A7: 3/8” Emitter, 953 dome foil, standard, stainless, 3/4” FPT, 1/4” FPT | B7: S003953X02 | C7: D09530003VXESFF | D7: 1490.5
A8: 3/8” Emitter, 954 cavity foil, escutcheon, stainless, 3/4” FPT, 1/4” FPT | B8: S003953031 | C8: D09530003VXE0CF | D8: 1490.5
A9: 3/8” Emitter, 954 cavity foil, standard, stainless, 3/4” FPT, 1/4” FPT | B9: S003953001 | C9: D09540003VXE0CF | D9: 1490.5
A10: 1/2” Emitter, 953 dome foil, standard, brass, 3/4” MPT, 1/4” FPT | B10: S006953400 | C10: D09530006VXE0B0 | D10: 1412.5
A11: 1/2” Emitter, 953 dome foil, standard, stainless, 3/4” MPT, 1/4” FPT | B11: S006953X40 | C11: D09530006VXE0XX | D11: 1412.5
A12: 1/2” Emitter, 953 dome foil, standard, PVDF, 3/4” MPT, 1/4” FPT | B12: S006953406 | C12: D09530006VXE0N0 | D12: 2622.5
... A36: 7/16-20 Female JIC x 36” PTFE lined braided stainless hose, 1/4” ID | B36: P360955228 | C36: D09550360VXJICX | D36: 668
A37: 1/8" MNPT x 7/16-20 Male JIC Straight Adapter, stainless | B37: P001950X00 | D37: 37.5
A38: 1/4" MNPT x 7/16-20 Male JIC Straight Adapter, brass | B38: PAY7000C01 | C38: D09550002VXMFBA | D38: 27.5
A39: 1/4" MNPT x 7/16-20 Male JIC Straight Adapter, stainless | B39: P002950X00 | D39: 35.5
A40: 1/4" MNPT x 7/16-20 Male JIC 90 Degree Adapter, stainless | B40: PS35950X00 | D40: 23
A41: 1/8" NPT x 1/4" OD Compression, Straight Adapter, polypropylene | B41: P003953028 | D41: 8
A42: 1/4" NPT x 3/8" OD Compression, Straight Adapter, polypropylene | B42: P000950019 | D42: 32.5
A43: 1” 951 Combination Panel, Dry Contact, Ball Valve | B43: S010951DRY | C43: D09510010VX3DC1 | D43: 51232
A44: 1” 951 Combination Panel, Active Release, Ball Valve | B44: S010951ACT | C44: D09510010VX3ARC | D44: 51450
A45: 1.5” 951 Combination Panel, Dry Contact, Ball Valve | B45: S014951DRY | C45: D09510014VX3DCC | D45: 53923.5
A46: 1.5” 951 Combination Panel, Active Release, Ball Valve | B46: S014951ACT | C46: D09510014VX3ARC | D46: 53930.5
A47: 1” 951 Fluid Panel, Dry Contact | B47: S010951F00 | C47: D09510010VX3DC2 | D47: 36054.5
A48: 1” 951 Fluid Panel, Active Release | B48: S010951FA0 | C48: D09510010VX3ARF | D48: 38650.5
A49: 1.5” 951 Fluid Panel, Dry Contact | B49: S014951F00 | C49: D09510014VX3DCF | D49: 38535
A50: 1.5” 951 Fluid Panel, Active Release | B50: S014951FA0 | C50: D09510014VX3ARF | D50: 39798.5
A51: 1.5” 951 Zone Panel, Dry Contact, Ball Valve | B51: S01495110A | C51: D09510014VX3DCZ | D51: 27103
A52: 2” 951 Zone Panel, Dry Contact, Ball Valve | B52: S02095110A | C52: D09510020VX3DCZ | D52: 31186
A53: Pressure Transducer, Standard, 0-100 psi | B53: P000951140 | C53: D09510000VXST00 | D53: 2181.5
A54: Pressure Transducer Spec. App, Explosion Proof | B54: P000951TRM | C54: D09510000VXTRVP | D54: 5143
... A106: Nozzle Cap, 1/4-1/2”,Standard Style Nozzle, Orange | B106: P002953260 | C106: D09530002VXC0OP | D106: 38.5
A107: Nozzle Cap, 1/8" Nozzle, Black | B107: P0019530B0 | D107: 16.5
A108: Nozzle Cap, 1/4-5/8" Nozzle, Black | B108: P006953522 | C108: D09530002VXE0BP | D108: 38.5
A109: Nozzle Cap, 1" Nozzle, Black | B109: P010953522 | D109: 12
A110: O-ring Kit, primary/ secondary | B110: K000950KIT | C110: K09500000VXPK00 | D110: 219
A111: Discharge Hose, 49L/50L, rt angle, 22.25” OAL | B111: P000955B29 | C111: D09550004VX40DH | D111: 624.5
A112: Discharge Hose, DOT 80L, rt angle, 13.5” OAL | B112: P000955A29 | C112: D09550080VX8DH0 | D112: 573
A113: Discharge Hose Check Valve | B113: S000950BA1 | C113: D09500006VXSICV | D113: 375
A114: 1/4” Pilot Hose, 300 mm, for adjacent cylinders | B114: S000950P32 | C114: D09500002VXSSP0 | D114: 128
...

Sheet 2.5.2025 Configurator
A1: 1/8” Emitter, 954 cavity foil, standard, PVDF, 3/8” FPT, 1/8” FPT | B1: S003953105 | C1: D09530000VXE0NM | D1: 3340.5
A2: 1/8” Emitter, 953 dome foil, standard, stainless, 3/8” FPT, 1/8” FPT | B2: S00195310X | C2: D09530000VXE0TX | D2: 3215
A3: 1/4” Emitter, 953 dome foil, standard, stainless, 3/4” FPT, 1/4” FPT | B3: S002953X4F | C3: D09530002VXESDF | D3: 3215
A4: 1/4” Emitter, 953 dome foil, escutcheon, stainless, 3/4” FPT, 1/4” FPT | B4: S002953X2E | C4: D09530002VXEEDF | D4: 3215
A5: 1/4” Emitter, 954 cavity foil, standard, PVDF, 3/8” FPT, 1/8” FPT | B5: S003953170 | C5: D09530002VXCVE0 | D5: 3339
A6: 3/8” Emitter, 953 dome foil, escutcheon, stainless, 3/4” FPT, 1/4” FPT | B6: S003953032 | C6: D09530003VXE0DF | D6: 1490.5
A7: 3/8” Emitter, 953 dome foil, standard, stainless, 3/4” FPT, 1/4” FPT | B7: S003953X02 | C7: D09530003VXESFF | D7: 1490.5
A8: 3/8” Emitter, 954 cavity foil, escutcheon, stainless, 3/4” FPT, 1/4” FPT | B8: S003953031 | C8: D09530003VXE0CF | D8: 1490.5
A9: 3/8” Emitter, 954 cavity foil, standard, stainless, 3/4” FPT, 1/4” FPT | B9: S003953001 | C9: D09540003VXE0CF | D9: 1490.5
A10: 1/2” Emitter, 953 dome foil, standard, brass, 3/4” MPT, 1/4” FPT | B10: S006953400 | C10: D09530006VXE0B0 | D10: 1412.5
A11: 1/2” Emitter, 953 dome foil, standard, stainless, 3/4” MPT, 1/4” FPT | B11: S006953X40 | C11: D09530006VXE0XX | D11: 1412.5
A12: 1/2” Emitter, 953 dome foil, standard, PVDF, 3/4” MPT, 1/4” FPT | B12: S006953406 | C12: D09530006VXE0N0 | D12: 2622.5
... A36: 7/16-20 Female JIC x 36” PTFE lined braided stainless hose, 1/4” ID | B36: P360955228 | C36: D09550360VXJICX | D36: 668
A37: 1/8" MNPT x 7/16-20 Male JIC Straight Adapter, stainless | B37: P001950X00 | D37: 37.5
A38: 1/4" MNPT x 7/16-20 Male JIC Straight Adapter, brass | B38: PAY7000C01 | C38: D09550002VXMFBA | D38: 27.5
A39: 1/4" MNPT x 7/16-20 Male JIC Straight Adapter, stainless | B39: P002950X00 | D39: 35.5
A40: 1/4" MNPT x 7/16-20 Male JIC 90 Degree Adapter, stainless | B40: PS35950X00 | D40: 23
A41: 1/8" NPT x 1/4" OD Compression, Straight Adapter, polypropylene | B41: P003953028 | D41: 8
A42: 1/4" NPT x 3/8" OD Compression, Straight Adapter, polypropylene | B42: P000950019 | D42: 32.5
A43: 1” 951 Combination Panel, Dry Contact, Ball Valve | B43: S010951DRY | C43: D09510010VX3DC1 | D43: 51232
A44: 1” 951 Combination Panel, Active Release, Ball Valve | B44: S010951ACT | C44: D09510010VX3ARC | D44: 51450
A45: 1.5” 951 Combination Panel, Dry Contact, Ball Valve | B45: S014951DRY | C45: D09510014VX3DCC | D45: 53923.5
A46: 1.5” 951 Combination Panel, Active Release, Ball Valve | B46: S014951ACT | C46: D09510014VX3ARC | D46: 53930.5
A47: 1” 951 Fluid Panel, Dry Contact | B47: S010951F00 | C47: D09510010VX3DC2 | D47: 36054.5
A48: 1” 951 Fluid Panel, Active Release | B48: S010951FA0 | C48: D09510010VX3ARF | D48: 38650.5
A49: 1.5” 951 Fluid Panel, Dry Contact | B49: S014951F00 | C49: D09510014VX3DCF | D49: 38535
A50: 1.5” 951 Fluid Panel, Active Release | B50: S014951FA0 | C50: D09510014VX3ARF | D50: 39798.5
A51: 1.5” 951 Zone Panel, Dry Contact, Ball Valve | B51: S01495110A | C51: D09510014VX3DCZ | D51: 27103
A52: 2” 951 Zone Panel, Dry Contact, Ball Valve | B52: S02095110A | C52: D09510020VX3DCZ | D52: 31186
A53: Pressure Transducer, Standard, 0-100 psi | B53: P000951140 | C53: D09510000VXST00 | D53: 2181.5
A54: Pressure Transducer Spec. App, Explosion Proof | B54: P000951TRM | C54: D09510000VXTRVP | D54: 5143
... A106: Nozzle Cap, 1/4-1/2”,Standard Style Nozzle, Orange | B106: P002953260 | C106: D09530002VXC0OP | D106: 38.5
A107: Nozzle Cap, 1/8" Nozzle, Black | B107: P0019530B0 | D107: 16.5
A108: Nozzle Cap, 1/4-5/8" Nozzle, Black | B108: P006953522 | C108: D09530002VXE0BP | D108: 38.5
A109: Nozzle Cap, 1" Nozzle, Black | B109: P010953522 | D109: 12
A110: O-ring Kit, primary/ secondary | B110: K000950KIT | C110: K09500000VXPK00 | D110: 219
A111: Discharge Hose, 49L/50L, rt angle, 22.25” OAL | B111: P000955B29 | C111: D09550004VX40DH | D111: 624.5
A112: Discharge Hose, DOT 80L, rt angle, 13.5” OAL | B112: P000955A29 | C112: D09550080VX8DH0 | D112: 573
A113: Discharge Hose Check Valve | B113: S000950BA1 | C113: D09500006VXSICV | D113: 375
A114: 1/4” Pilot Hose, 300 mm, for adjacent cylinders | B114: S000950P32 | C114: D09500002VXSSP0 | D114: 128
...

Sheet 1.7.2026 Configurator
A1: 1/8” Emitter, 954 cavity foil, standard, PVDF, 3/8” FPT, 1/8” FPT | B1: S003953105 | C1: D09530000VXE0NM | D1: 3340.5 | E1: 1
A2: 1/8” Emitter, 953 dome foil, standard, stainless, 3/8” FPT, 1/8” FPT | B2: S00195310X | C2: D09530000VXE0TX | D2: 3215 | E2: 1
A3: 1/4” Emitter, 953 dome foil, standard, stainless, 3/4” FPT, 1/4” FPT | B3: S002953X4F | C3: D09530002VXESDF | D3: 3215 | E3: 1
A4: 1/4” Emitter, 953 dome foil, escutcheon, stainless, 3/4” FPT, 1/4” FPT | B4: S002953X2E | C4: D09530002VXEEDF | D4: 3215 | E4: 1
A5: 1/4” Emitter, 954 cavity foil, standard, PVDF, 3/8” FPT, 1/8” FPT | B5: S003953170 | C5: D09530002VXCVE0 | D5: 3339 | E5: 1
A6: 3/8” Emitter, 953 dome foil, escutcheon, stainless, 3/4” FPT, 1/4” FPT | B6: S003953032 | C6: D09530003VXE0DF | D6: 1490.5 | E6: 1
A7: 3/8” Emitter, 953 dome foil, standard, stainless, 3/4” FPT, 1/4” FPT | B7: S003953X02 | C7: D09530003VXESFF | D7: 1490.5 | E7: 1
A8: 3/8” Emitter, 954 cavity foil, escutcheon, stainless, 3/4” FPT, 1/4” FPT | B8: S003953031 | C8: D09530003VXE0CF | D8: 1490.5 | E8: 1
A9: 3/8” Emitter, 954 cavity foil, standard, stainless, 3/4” FPT, 1/4” FPT | B9: S003953001 | C9: D09540003VXE0CF | D9: 1490.5 | E9: 1
A10: 1/2” Emitter, 953 dome foil, standard, brass, 3/4” MPT, 1/4” FPT | B10: S006953400 | C10: D09530006VXE0B0 | D10: 1412.5 | E10: 1
A11: 1/2” Emitter, 953 dome foil, standard, stainless, 3/4” MPT, 1/4” FPT | B11: S006953X40 | C11: D09530006VXE0XX | D11: 1412.5 | E11: 1
A12: 1/2” Emitter, 953 dome foil, standard, PVDF, 3/4” MPT, 1/4” FPT | B12: S006953406 | C12: D09530006VXE0N0 | D12: 2622.5 | E12: 1
... A36: 7/16-20 Female JIC x 36” PTFE lined braided stainless hose, 1/4” ID | B36: P360955228 | C36: D09550360VXJICX | D36: 668 | E36: 1
A37: 1/8" MNPT x 7/16-20 Male JIC Straight Adapter, stainless | B37: P001950X00 | D37: 37.5 | E37: 1
A38: 1/4" MNPT x 7/16-20 Male JIC Straight Adapter, brass | B38: PAY7000C01 | C38: D09550002VXMFBA | D38: 27.5 | E38: 1
A39: 1/4" MNPT x 7/16-20 Male JIC Straight Adapter, stainless | B39: P002950X00 | D39: 35.5 | E39: 1
A40: 1/4" MNPT x 7/16-20 Male JIC 90 Degree Adapter, stainless | B40: PS35950X00 | D40: 23 | E40: 1
A41: 1/8" NPT x 1/4" OD Compression, Straight Adapter, polypropylene | B41: P003953028 | D41: 8 | E41: 1
A42: 1/4" NPT x 3/8" OD Compression, Straight Adapter, polypropylene | B42: P000950019 | D42: 32.5 | E42: 1
A43: 1” 951 Combination Panel, Dry Contact, Ball Valve | B43: S010951DRY | C43: D09510010VX3DC1 | D43: 51232 | E43: 1
A44: 1” 951 Combination Panel, Active Release, Ball Valve | B44: S010951ACT | C44: D09510010VX3ARC | D44: 51450 | E44: 1
A45: 1.5” 951 Combination Panel, Dry Contact, Ball Valve | B45: S014951DRY | C45: D09510014VX3DCC | D45: 53923.5 | E45: 1
A46: 1.5” 951 Combination Panel, Active Release, Ball Valve | B46: S014951ACT | C46: D09510014VX3ARC | D46: 53930.5 | E46: 1
A47: 1” 951 Fluid Panel, Dry Contact | B47: S010951F00 | C47: D09510010VX3DC2 | D47: 36054.5 | E47: 1
A48: 1” 951 Fluid Panel, Active Release | B48: S010951FA0 | C48: D09510010VX3ARF | D48: 38650.5 | E48: 1
A49: 1.5” 951 Fluid Panel, Dry Contact | B49: S014951F00 | C49: D09510014VX3DCF | D49: 38535 | E49: 1
A50: 1.5” 951 Fluid Panel, Active Release | B50: S014951FA0 | C50: D09510014VX3ARF | D50: 39798.5 | E50: 1
A51: 1.5” 951 Zone Panel, Dry Contact, Ball Valve | B51: S01495110A | C51: D09510014VX3DCZ | D51: 27103 | E51: 1
A52: 2” 951 Zone Panel, Dry Contact, Ball Valve | B52: S02095110A | C52: D09510020VX3DCZ | D52: 31186 | E52: 1
A53: Pressure Transducer, Standard, 0-100 psi | B53: P000951140 | C53: D09510000VXST00 | D53: 2181.5 | E53: 1
A54: Pressure Transducer Spec. App, Explosion Proof | B54: P000951TRM | C54: D09510000VXTRVP | D54: 5143 | E54: 1
... A96: 1/2 MNPT x 36” Stainless Steel Hose for Water Tank Regulator | B96: P004950010 | C96: P09500004ZZ0WTR | D96: 1032 | E96: 1
A97: D/950 WATER TANK ASY UPDATED DESIGN 100L SS316L CE | B97: D09500000VXWTXA | C97: D09500000VXWTX1 | D97: 33244.5
A98: D/950 WATER TANK ASY 150L SS316L CE | B98: D09500000VXWTXA | C98: D09500000VXWTXS | D98: 39076
A99: D/950 WATER TANK ASY 300L SS316L CE | B99: D09500000VXWTXA | C99: D09500000VXWTX3 | D99: 48170
A100: D/950 WATER TANK ASY 500L SS316L CE | B100: S000950X50 | C100: D09500000VXWTX5 | D100: 39381.5
A101: D/950 WATER TANK ASY 750L SS316L CE | B101: D09500000VXWTXA | C101: D09500000VXWTX7 | D101: 57134
A102: D/950 WATER TANK ASY 1000L SS316L CE | B102: D09500000VXWTXA | C102: D09500000VXWTXA | D102: 62405
A103: Nozzle Cap, 1/4-1/2”,Standard Style Nozzle, Orange | B103: P002953260 | C103: D09530002VXC0OP | D103: 38.5 | E103: 1
A104: Nozzle Cap, 1/8" Nozzle, Black | B104: P0019530B0 | D104: 16.5 | E104: 1
...

Sheet 10.28.2025 Configurator
A1: 1/8” Emitter, 954 cavity foil, standard, PVDF, 3/8” FPT, 1/8” FPT | B1: S003953105 | C1: D09530000VXE0NM | D1: 3181
A2: 1/8” Emitter, 953 dome foil, standard, stainless, 3/8” FPT, 1/8” FPT | B2: S00195310X | C2: D09530000VXE0TX | D2: 3061.5
A3: 1/4” Emitter, 953 dome foil, standard, stainless, 3/4” FPT, 1/4” FPT | B3: S002953X4F | C3: D09530002VXESDF | D3: 3061.5
A4: 1/4” Emitter, 954 cavity foil, standard, PVDF, 3/8” FPT, 1/8” FPT | B4: S003953170 | C4: D09530002VXCVE0 | D4: 3180
A5: 1/4” Emitter, 953 dome foil, escutcheon, stainless, 3/4” FPT, 1/4” FPT | B5: S002953X2E | C5: D09530002VXEEDF | D5: 3061.5
A6: 3/8” Emitter, 953 dome foil, escutcheon, stainless, 3/4” FPT, 1/4” FPT | B6: S003953032 | C6: D09530003VXE0DF | D6: 1419.5
A7: 3/8” Emitter, 953 dome foil, standard, stainless, 3/4” FPT, 1/4” FPT | B7: S003953X02 | C7: D09530003VXESFF | D7: 1419.5
A8: 3/8” Emitter, 954 cavity foil, escutcheon, stainless, 3/4” FPT, 1/4” FPT | B8: S003953031 | C8: D09530003VXE0CF | D8: 1419.5
A9: 3/8” Emitter, 954 cavity foil, standard, stainless, 3/4” FPT, 1/4” FPT | B9: S003953001 | C9: D09540003VXE0CF | D9: 1419.5
A10: 1/2” Emitter, 953 dome foil, standard, brass, 3/4” MPT, 1/4” FPT | B10: S006953400 | C10: D09530006VXE0B0 | D10: 1345
A11: 1/2” Emitter, 953 dome foil, standard, PVDF, 3/4” MPT, 1/4” FPT | B11: S006953406 | C11: D09530006VXE0N0 | D11: 2497.5
A12: 1/2” Emitter, 953 dome foil, escutcheon, stainless, 3/4” FPT, 1/4” FPT | B12: S004953511 | C12: D09530004VXE0D4 | D12: 1419.5
... A150: Plug for Manifold | B150: P006000Z07 | C150: P00000006NPTV00 | D150: 21.5

Sheet 9.9.2025 Configurator
A1: 1/8” Emitter, 954 cavity foil, standard, PVDF, 3/8” FPT, 1/8” FPT | B1: S003953105 | C1: D09530000VXE0NM | D1: 3181
A2: 1/8” Emitter, 953 dome foil, standard, stainless, 3/8” FPT, 1/8” FPT | B2: S00195310X | C2: D09530000VXE0TX | D2: 3061.5
A3: 1/4” Emitter, 953 dome foil, standard, stainless, 3/4” MPT, 1/4” FPT | B3: S002953X02 | C3: D09530002VXEXDF | D3: 3550
A4: 1/4” Emitter, 954 cavity foil, standard, PVDF, 3/8” FPT, 1/8” FPT | B4: S003953170 | C4: D09530002VXCVE0 | D4: 3180
A5: 3/8” Emitter, 953 dome foil, escutcheon, stainless, 3/4” FPT, 1/4” FPT | B5: S003953032 | C5: D09530003VXE0DF | D5: 1419.5
A6: 3/8” Emitter, 953 dome foil, standard, stainless, 3/4” FPT, 1/4” FPT | B6: S003953034 | C6: D09530003VXESDF | D6: 1345
A7: 3/8” Emitter, 954 cavity foil, escutcheon, stainless, 3/4” FPT, 1/4” FPT | B7: S003953031 | C7: D09530003VXE0CF | D7: 1419.5
A8: 3/8” Emitter, 954 cavity foil, standard, stainless, 3/4” FPT, 1/4” FPT | B8: S003953033 | C8: D09530003VXESCF | D8: 1345
A9: 1/2” Emitter, 953 dome foil, standard, brass, 3/4” MPT, 1/4” FPT | B9: S006953400 | C9: D09530006VXE0B0 | D9: 1345
A10: 1/2” Emitter, 953 dome foil, standard, PVDF, 3/4” MPT, 1/4” FPT | B10: S006953406 | C10: D09530006VXE0N0 | D10: 2497.5
A11: 1/2” Emitter, 953 dome foil, escutcheon, stainless, 3/4” FPT, 1/4” FPT | B11: S004953511 | C11: D09530004VXE0D4 | D11: 1419.5
A12: 1/2” Emitter, 953 dome foil, standard, stainless, 3/4” FPT, 1/4” FPT | B12: S004953513 | C12: D09530004VXESDF | D12: 1873.5
... A146: 10 Gallon Water Tank, Red, w/ Trim, ASME, FM and CE approved | B146: S10095014C | C146: D09500010VXWTRC | D146: 19369

Sheet 8.19.2025 Configurator
A1: 1/8” Emitter, 954 cavity foil, standard, PVDF, 3/8” FPT, 1/8” FPT | B1: S003953105 | C1: D09530000VXE0NM | D1: 3181
A2: 1/8” Emitter, 953 dome foil, standard, stainless, 3/8” FPT, 1/8” FPT | B2: S00195310X | C2: D09530000VXE0TX | D2: 3061.5
A3: 1/4” Emitter, 953 dome foil, standard, stainless, 3/4” MPT, 1/4” FPT | B3: S002953X02 | C3: D09530002VXEXDF | D3: 3550
A4: 1/4” Emitter, 954 cavity foil, standard, PVDF, 3/8” FPT, 1/8” FPT | B4: S003953170 | C4: D09530002VXCVE0 | D4: 3180
A5: 3/8” Emitter, 953 dome foil, escutcheon, stainless, 3/4” FPT, 1/4” FPT | B5: S003953032 | C5: D09530003VXE0DF | D5: 1419.5
A6: 3/8” Emitter, 953 dome foil, standard, stainless, 3/4” FPT, 1/4” FPT | B6: S003953034 | C6: D09530003VXESDF | D6: 1345
A7: 3/8” Emitter, 954 cavity foil, escutcheon, stainless, 3/4” FPT, 1/4” FPT | B7: S003953031 | C7: D09530003VXE0CF | D7: 1419.5
A8: 3/8” Emitter, 954 cavity foil, standard, stainless, 3/4” FPT, 1/4” FPT | B8: S003953033 | C8: D09530003VXESCF | D8: 1345
A9: 1/2” Emitter, 953 dome foil, standard, brass, 3/4” MPT, 1/4” FPT | B9: S006953400 | C9: D09530006VXE0B0 | D9: 1345
A10: 1/2” Emitter, 953 dome foil, standard, PVDF, 3/4” MPT, 1/4” FPT | B10: S006953406 | C10: D09530006VXE0N0 | D10: 2497.5
A11: 1/2” Emitter, 953 dome foil, escutcheon, stainless, 3/4” FPT, 1/4” FPT | B11: S004953511 | C11: D09530004VXE0D4 | D11: 1419.5
A12: 1/2” Emitter, 953 dome foil, standard, stainless, 3/4” FPT, 1/4” FPT | B12: S004953513 | C12: D09530004VXESDF | D12: 1873.5
... A145: D/950 WATER TANK ASY 1000L SS316L CE | B145: D09500000VXWTXA | C145: D09500000VXWTXA | D145: 59433

Sheet 6.23.2025 Configurator
A1: 1/8” Emitter, 954 cavity foil, standard, PVDF, 3/8” FPT, 1/8” FPT | B1: S003953105 | C1: D09530000VXE0NM | D1: 3181
A2: 1/8” Emitter, 953 dome foil, standard, stainless, 3/8” FPT, 1/8” FPT | B2: S00195310X | C2: D09530000VXE0TX | D2: 3061.5
A3: 1/4” Emitter, 953 dome foil, standard, stainless, 3/4” MPT, 1/4” FPT | B3: S002953X02 | C3: D09530002VXEXDF | D3: 3550
A4: 1/4” Emitter, 954 cavity foil, standard, PVDF, 3/8” FPT, 1/8” FPT | B4: S003953170 | C4: D09530002VXCVE0 | D4: 3180
A5: 3/8” Emitter, 953 dome foil, escutcheon, stainless, 3/4” FPT, 1/4” FPT | B5: S003953032 | C5: D09530003VXE0DF | D5: 1419.5
A6: 3/8” Emitter, 953 dome foil, standard, stainless, 3/4” FPT, 1/4” FPT | B6: S003953034 | C6: D09530003VXESDF | D6: 1345
A7: 3/8” Emitter, 954 cavity foil, escutcheon, stainless, 3/4” FPT, 1/4” FPT | B7: S003953031 | C7: D09530003VXE0CF | D7: 1419.5
A8: 3/8” Emitter, 954 cavity foil, standard, stainless, 3/4” FPT, 1/4” FPT | B8: S003953033 | C8: D09530003VXESCF | D8: 1345
A9: 1/2” Emitter, 953 dome foil, standard, brass, 3/4” MPT, 1/4” FPT | B9: S006953400 | C9: D09530006VXE0B0 | D9: 1345
A10: 1/2” Emitter, 953 dome foil, standard, PVDF, 3/4” MPT, 1/4” FPT | B10: S006953406 | C10: D09530006VXE0N0 | D10: 2497.5
A11: 1/2” Emitter, 953 dome foil, escutcheon, stainless, 3/4” FPT, 1/4” FPT | B11: S004953511 | C11: D09530004VXE0D4 | D11: 1419.5
A12: 1/2” Emitter, 953 dome foil, standard, stainless, 3/4” FPT, 1/4” FPT | B12: S004953513 | C12: D09530004VXESDF | D12: 1873.5
... A149: VICTAULIC VORTEX NITROGEN CYL - 80L W/VALVE UNPRESSURIZED | B149: S000950E01 | C149: D09500000VX8CE0 | D149: 5593

Sheet 4.28.2025 Configurator
A1: 1/8” Emitter, 954 cavity foil, standard, PVDF, 3/8” FPT, 1/8” FPT | B1: S003953105 | C1: D09530000VXE0NM | D1: 2986.5
A2: 1/8” Emitter, 953 dome foil, standard, stainless, 3/8” FPT, 1/8” FPT | B2: S00195310X | C2: D09530000VXE0TX | D2: 2874.5
A3: 1/4” Emitter, 953 dome foil, standard, stainless, 3/4” MPT, 1/4” FPT | B3: S002953X02 | C3: D09530002VXEXDF | D3: 3333
A4: 1/4” Emitter, 954 cavity foil, standard, PVDF, 3/8” FPT, 1/8” FPT | B4: S003953170 | C4: D09530002VXCVE0 | D4: 2985.5
A5: 3/8” Emitter, 953 dome foil, escutcheon, stainless, 3/4” FPT, 1/4” FPT | B5: S003953032 | C5: D09530003VXE0DF | D5: 1332.5
A6: 3/8” Emitter, 953 dome foil, standard, stainless, 3/4” FPT, 1/4” FPT | B6: S003953034 | C6: D09530003VXESDF | D6: 1262.5
A7: 3/8” Emitter, 954 cavity foil, escutcheon, stainless, 3/4” FPT, 1/4” FPT | B7: S003953031 | C7: D09530003VXE0CF | D7: 1332.5
A8: 3/8” Emitter, 954 cavity foil, standard, stainless, 3/4” FPT, 1/4” FPT | B8: S003953033 | C8: D09530003VXESCF | D8: 1262.5
A9: 1/2” Emitter, 953 dome foil, standard, brass, 3/4” MPT, 1/4” FPT | B9: S006953400 | C9: D09530006VXE0B0 | D9: 1262.5
A10: 1/2” Emitter, 953 dome foil, standard, PVDF, 3/4” MPT, 1/4” FPT | B10: S006953406 | C10: D09530006VXE0N0 | D10: 2345
A11: 1/2” Emitter, 953 dome foil, escutcheon, stainless, 3/4” FPT, 1/4” FPT | B11: S004953511 | C11: D09530004VXE0D4 | D11: 1332.5
A12: 1/2” Emitter, 953 dome foil, standard, stainless, 3/4” FPT, 1/4” FPT | B12: S004953513 | C12: D09530004VXESDF | D12: 1759
... A149: VICTAULIC VORTEX NITROGEN CYL - 80L W/VALVE UNPRESSURIZED | B149: S000950E01 | C149: D09500000VX8CE0 | D149: 5251.5

Sheet EMEA Updated 2025
B1: Victaulic Vortex® System Product List Price Effective March 1st, 2025
B2: United States
H4: Multiplier:
B5: NOTE: Please add information to the cells shaded in | C5: GREEN. | H5: 0.37
B7: Option Style | C7: Shipping Weight | D7: Item BPCS Number | E7: M3 Item Number | F7: Cost (USD) | G7: List Price (USD) | H7: Extended Price | I7: GM % | J7: 60% Margin Sell | K7: 67.5% Margin Sell | L7: 75% Margin Sell
B9: Emitters | J9: 0.6 | K9: 0.675 | L9: 0.75
B10: 1/8" Emitters
B11: 1/8” Emitter, 954 cavity foil, standard, PVDF, 3/8” FPT, 1/8” FPT | C11: 1 | D11: S003953105 | E11: =VLOOKUP(D11,Sheet1!B:C, 2, FALSE) -> D09530000VXE0NM | F11: 195.71 | G11: ='March 2025'!F11 -> 2986.5 | H11: =G11*$H$5 -> 1105.005 | I11: =((H11-F11)/H11) -> 0.82288768 | J11: =(($F11/(1-$J9))) -> 489.275 | K11: =(($F11/(1-$K$9))) -> 602.18462 | L11: =(($F11/(1-$L9))) -> 782.84
B12: 1/8” Emitter, 953 dome foil, standard, stainless, 3/8” FPT, 1/8” FPT | C12: 1 | D12: S00195310X | E12: =VLOOKUP(D12,Sheet1!B:C, 2, FALSE) -> D09530000VXE0TX | F12: 171.534 | G12: ='March 2025'!F12 -> 2874.5 | H12: =G12*$H$5 -> 1063.565 | I12: =((H12-F12)/H12) -> 0.8387179 | J12: =(($F12/(1-$J$9))) -> 428.835 | K12: =(($F12/(1-$K$9))) -> 527.79692 | L12: =(($F12/(1-$L$9))) -> 686.136
B13: 1/4" Emitters
B14: 1/4” Emitter, 953 dome foil, standard, stainless, 3/4” MPT, 1/4” FPT | C14: 1 | D14: S002953X02 | E14: =VLOOKUP(D14,Sheet1!B:C, 2, FALSE) -> D09530002VXEXDF | F14: 160.1174 | G14: ='March 2025'!F14 -> 3333 | H14: =G14*$H$5 -> 1233.21 | I14: =((H14-F14)/H14) -> 0.8701621 | J14: =(($F14/(1-J$9))) -> 400.2935 | K14: =(($F14/(1-$K$9))) -> 492.66892 | L14: =(($F14/(1-L$9))) -> 640.4696
B15: 1/4” Emitter, 954 cavity foil, standard, PVDF, 3/8” FPT, 1/8” FPT | C15: 1 | D15: S003953170 | E15: =VLOOKUP(D15,Sheet1!B:C, 2, FALSE) -> D09530002VXCVE0 | F15: 241.4136 | G15: ='March 2025'!F15 -> 2985.5 | H15: =G15*$H$5 -> 1104.635 | I15: =((H15-F15)/H15) -> 0.78145396 | J15: =(($F15/(1-$J$9))) -> 603.534 | K15: =(($F15/(1-$K$9))) -> 742.81108 | L15: =(($F15/(1-$L$9))) -> 965.6544
B16: 3/8" Emitters
A17: NEW | B17: 3/8” Emitter, 953 dome foil, escutcheon, stainless, 3/4” FPT, 1/4” FPT | C17: 1 | D17: S003953032 | E17: =VLOOKUP(D17,Sheet1!B:C, 2, FALSE) -> D09530003VXE0DF | F17: 52.3201 | G17: ='March 2025'!F17 -> 1332.5 | H17: =G17*$H$5 -> 493.025 | I17: =((H17-F17)/H17) -> 0.89387942 | J17: =(($F17/(1-J$9))) -> 130.80025 | K17: =(($F17/(1-$K$9))) -> 160.98492 | L17: =(($F17/(1-L$9))) -> 209.2804
A18: NEW | B18: 3/8” Emitter, 953 dome foil, standard, stainless, 3/4” FPT, 1/4” FPT | C18: 1 | D18: S003953034 | E18: =VLOOKUP(D18,Sheet1!B:C, 2, FALSE) -> D09530003VXESDF | F18: 34.5438 | G18: ='March 2025'!F18 -> 1262.5 | H18: =G18*$H$5 -> 467.125 | I18: =((H18-F18)/H18) -> 0.9260502 | J18: =(($F18/(1-J$9))) -> 86.3595 | K18: =(($F18/(1-$K$9))) -> 106.28862 | L18: =(($F18/(1-L$9))) -> 138.1752
A19: NEW | B19: 3/8” Emitter, 954 cavity foil, escutcheon, stainless, 3/4” FPT, 1/4” FPT | C19: 1 | D19: S003953031 | E19: =VLOOKUP(D19,Sheet1!B:C, 2, FALSE) -> D09530003VXE0CF | F19: 51.85424 | G19: ='March 2025'!F19 -> 1332.5 | H19: =G19*$H$5 -> 493.025 | I19: =((H19-F19)/H19) -> 0.89482432 | J19: =(($F19/(1-J$9))) -> 129.6356 | K19: =(($F19/(1-$K$9))) -> 159.55151 | L19: =(($F19/(1-L$9))) -> 207.41696
A20: NEW | B20: 3/8” Emitter, 954 cavity foil, standard, stainless, 3/4” FPT, 1/4” FPT | C20: 1 | D20: S003953033 | E20: =VLOOKUP(D20,Sheet1!B:C, 2, FALSE) -> D09530003VXESCF | F20: 34.07794 | G20: ='March 2025'!F20 -> 1262.5 | H20: =G20*$H$5 -> 467.125 | I20: =((H20-F20)/H20) -> 0.92704749 | J20: =(($F20/(1-J$9))) -> 85.19485 | K20: =(($F20/(1-$K$9))) -> 104.8552 | L20: =(($F20/(1-L$9))) -> 136.31176
B21: 1/2" Emitters
B22: 1/2” Emitter, 953 dome foil, standard, brass, 3/4” MPT, 1/4” FPT | C22: 1 | D22: S006953400 | E22: =VLOOKUP(D22,Sheet1!B:C, 2, FALSE) -> D09530006VXE0B0 | F22: 102.34866 | G22: ='March 2025'!F22 -> 1262.5 | H22: =G22*$H$5 -> 467.125 | I22: =((H22-F22)/H22) -> 0.78089663 | J22: =(($F22/(1-J$9))) -> 255.87165 | K22: =(($F22/(1-$K$9))) -> 314.91895 | L22: =(($F22/(1-L$9))) -> 409.39464
B23: 1/2” Emitter, 953 dome foil, standard, PVDF, 3/4” MPT, 1/4” FPT | C23: 1 | D23: S006953406 | E23: =VLOOKUP(D23,Sheet1!B:C, 2, FALSE) -> D09530006VXE0N0 | F23: 230.5925 | G23: ='March 2025'!F23 -> 2345 | H23: =G23*$H$5 -> 867.65 | I23: =((H23-F23)/H23) -> 0.73423327 | J23: =(($F23/(1-J$9))) -> 576.48125 | K23: =(($F23/(1-$K$9))) -> 709.51538 | L23: =(($F23/(1-L$9))) -> 922.37
A24: NEW | B24: 1/2” Emitter, 953 dome foil, escutcheon, stainless, 3/4” FPT, 1/4” FPT | C24: 1 | D24: S004953511 | E24: =VLOOKUP(D24,Sheet1!B:C, 2, FALSE) -> D09530004VXE0D4 | F24: 60.22 | G24: ='March 2025'!F24 -> 1332.5 | H24: =G24*$H$5 -> 493.025 | I24: =((H24-F24)/H24) -> 0.87785609 | J24: =(($F24/(1-J$9))) -> 150.55 | K24: =(($F24/(1-$K$9))) -> 185.29231 | L24: =(($F24/(1-L$9))) -> 240.88
A25: NEW | B25: 1/2” Emitter, 953 dome foil, standard, stainless, 3/4” FPT, 1/4” FPT | C25: 1 | D25: S004953513 | E25: =VLOOKUP(D25,Sheet1!B:C, 2, FALSE) -> D09530004VXESDF | F25: 35.2038 | G25: ='March 2025'!F25 -> 1759 | H25: =G25*$H$5 -> 650.83 | I25: =((H25-F25)/H25) -> 0.94590938 | J25: =(($F25/(1-J$9))) -> 88.0095 | K25: =(($F25/(1-$K$9))) -> 108.31938 | L25: =(($F25/(1-L$9))) -> 140.8152
B26: 5/8" Emitters
B27: 5/8” Emitter, 954 cavity foil, standard, PVDF, 3/4” FPT, 1/4" FPT | C27: 1 | D27: S006953503 | E27: =VLOOKUP(D27,Sheet1!B:C, 2, FALSE) -> D09530005VXCVE0 | F27: 193.3368 | G27: ='March 2025'!F27 -> 2986.5 | H27: =G27*$H$5 -> 1105.005 | I27: =((H27-F27)/H27) -> 0.82503536 | J27: =(($F27/(1-J$9))) -> 483.342 | K27: =(($F27/(1-$K$9))) -> 594.88246 | L27: =(($F27/(1-L$9))) -> 773.3472
A28: NEW | B28: 5/8” Emitter, 954 cavity foil, escutcheon, stainless, 3/4” FPT, 1/4” FPT | C28: 1 | D28: S006953512 | E28: =VLOOKUP(D28,Sheet1!B:C, 2, FALSE) -> D09530005VXE0CF | F28: 50.4801 | G28: ='March 2025'!F28 -> 1332.5 | H28: =G28*$H$5 -> 493.025 | I28: =((H28-F28)/H28) -> 0.89761148 | J28: =(($F28/(1-J$9))) -> 126.20025 | K28: =(($F28/(1-$K$9))) -> 155.32338 | L28: =(($F28/(1-L$9))) -> 201.9204
A29: NEW | B29: 5/8” Emitter, 954 cavity foil, standard, stainless, 3/4” FPT, 1/4” FPT | C29: 1 | D29: S006953514 | E29: =VLOOKUP(D29,Sheet1!B:C, 2, FALSE) -> D09530005VXESCF | F29: 32.7038 | G29: ='March 2025'!F29 -> 1262.5 | H29: =G29*$H$5 -> 467.125 | I29: =((H29-F29)/H29) -> 0.92998919 | J29: =(($F29/(1-J$9))) -> 81.7595 | K29: =(($F29/(1-$K$9))) -> 100.62708 | L29: =(($F29/(1-L$9))) -> 130.8152
B30: 1" Emitters
A31: NEW | B31: 1” Emitter, 953/954 dome foil, escutcheon, stainless, 1” FPT, 1/8” FPT | C31: 1 | D31: S010953511 | E31: =VLOOKUP(D31,Sheet1!B:C, 2, FALSE) -> D09530010VXE0DF | F31: 68.4904 | G31: ='March 2025'!F31 -> 2316.5 | H31: =G31*$H$5 -> 857.105 | I31: =((H31-F31)/H31) -> 0.920091 | J31: =(($F31/(1-J$9))) -> 171.226 | K31: =(($F31/(1-$K$9))) -> 210.73969 | L31: =(($F31/(1-L$9))) -> 273.9616
B33: Water Flow Kits (Strainer, Flow Cartridge, Emitter Trim Kit)
B34: Water Flow Cartridge Kit, .13 GPM, Brass, 3/4” NPT | C34: 1 | D34: K000953013 | E34: =VLOOKUP(D34,Sheet1!B:C, 2, FALSE) -> D09530006VXWCB3 | F34: 103.42 | G34: ='March 2025'!F34 -> 1310 | H34: =G34*$H$5 -> 484.7 | I34: =((H34-F34)/H34) -> 0.78663091 | J34: =(($F34/(1-J$9))) -> 258.55 | K34: =(($F34/(1-$K$9))) -> 318.21538 | L34: =(($F34/(1-L$9))) -> 413.68
B35: Water Flow Cartridge Kit, .13 GPM, Stainless, 3/4” NPT | C35: 1 | D35: K000953X13 | E35: =VLOOKUP(D35,Sheet1!B:C, 2, FALSE) -> D09530006VXWCX3 | F35: 133.39 | G35: ='March 2025'!F35 -> 1556.5 | H35: =G35*$H$5 -> 575.905 | I35: =((H35-F35)/H35) -> 0.76838194 | J35: =(($F35/(1-J$9))) -> 333.475 | K35: =(($F35/(1-$K$9))) -> 410.43077 | L35: =(($F35/(1-L$9))) -> 533.56
B36: Water Flow Cartridge Kit, .26 GPM, Brass, 3/4” NPT | C36: 1 | D36: K000953026 | E36: =VLOOKUP(D36,Sheet1!B:C, 2, FALSE) -> D09530006VXWCB4 | F36: 109.44 | G36: ='March 2025'!F36 -> 1310 | H36: =G36*$H$5 -> 484.7 | I36: =((H36-F36)/H36) -> 0.77421085 | J36: =(($F36/(1-J$9))) -> 273.6 | K36: =(($F36/(1-$K$9))) -> 336.73846 | L36: =(($F36/(1-L$9))) -> 437.76
B37: Water Flow Cartridge Kit, .26 GPM, Stainless, 3/4” NPT | C37: 1 | D37: K000953X26 | E37: =VLOOKUP(D37,Sheet1!B:C, 2, FALSE) -> D09530006VXWCX4 | F37: 133.39 | G37: ='March 2025'!F37 -> 1556.5 | H37: =G37*$H$5 -> 575.905 | I37: =((H37-F37)/H37) -> 0.76838194 | J37: =(($F37/(1-J$9))) -> 333.475 | K37: =(($F37/(1-$K$9))) -> 410.43077 | L37: =(($F37/(1-L$9))) -> 533.56
B38: Water Flow Cartridge Kit, .53 GPM, Brass, 3/4” NPT | C38: 1 | D38: K000953053 | E38: =VLOOKUP(D38,Sheet1!B:C, 2, FALSE) -> D09530006VXWCB5 | F38: 103.42 | G38: ='March 2025'!F38 -> 1310 | H38: =G38*$H$5 -> 484.7 | I38: =((H38-F38)/H38) -> 0.78663091 | J38: =(($F38/(1-J$9))) -> 258.55 | K38: =(($F38/(1-$K$9))) -> 318.21538 | L38: =(($F38/(1-L$9))) -> 413.68
B39: Water Flow Cartridge Kit, .53 GPM, Stainless, 3/4” NPT | C39: 1 | D39: K000953X53 | E39: =VLOOKUP(D39,Sheet1!B:C, 2, FALSE) -> D09530006VXWCX5 | F39: 135.51 | G39: ='March 2025'!F39 -> 1556.5 | H39: =G39*$H$5 -> 575.905 | I39: =((H39-F39)/H39) -> 0.76470078 | J39: =(($F39/(1-J$9))) -> 338.775 | K39: =(($F39/(1-$K$9))) -> 416.95385 | L39: =(($F39/(1-L$9))) -> 542.04
B40: Water Flow Cartridge Kit, .79 GPM, Brass, 3/4” NPT | C40: 1 | D40: K000953079 | E40: =VLOOKUP(D40,Sheet1!B:C, 2, FALSE) -> D09530006VXWCB7 | F40: 103.42 | G40: ='March 2025'!F40 -> 1310 | H40: =G40*$H$5 -> 484.7 | I40: =((H40-F40)/H40) -> 0.78663091 | J40: =(($F40/(1-J$9))) -> 258.55 | K40: =(($F40/(1-$K$9))) -> 318.21538 | L40: =(($F40/(1-L$9))) -> 413.68
B41: Water Flow Cartridge Kit, .79 GPM, Stainless, 3/4” NPT | C41: 1 | D41: K000953X79 | E41: =VLOOKUP(D41,Sheet1!B:C, 2, FALSE) -> D09530006VXWCX7 | F41: 135.51 | G41: ='March 2025'!F41 -> 1556.5 | H41: =G41*$H$5 -> 575.905 | I41: =((H41-F41)/H41) -> 0.76470078 | J41: =(($F41/(1-J$9))) -> 338.775 | K41: =(($F41/(1-$K$9))) -> 416.95385 | L41: =(($F41/(1-L$9))) -> 542.04
B42: Water Flow Cartridge Kit, 1.06 GPM, Brass, 3/4” NPT | C42: 1 | D42: K000953106 | E42: =VLOOKUP(D42,Sheet1!B:C, 2, FALSE) -> D09530006VXWCB6 | F42: 103.42 | G42: ='March 2025'!F42 -> 1310 | H42: =G42*$H$5 -> 484.7 | I42: =((H42-F42)/H42) -> 0.78663091 | J42: =(($F42/(1-J$9))) -> 258.55 | K42: =(($F42/(1-$K$9))) -> 318.21538 | L42: =(($F42/(1-L$9))) -> 413.68
B43: Water Flow Cartridge Kit, 1.06 GPM, Stainless, 3/4” NPT | C43: 1 | D43: K000953X06 | E43: =VLOOKUP(D43,Sheet1!B:C, 2, FALSE) -> D09530006VXWCX6 | F43: 135.51 | G43: ='March 2025'!F43 -> 1556.5 | H43: =G43*$H$5 -> 575.905 | I43: =((H43-F43)/H43) -> 0.76470078 | J43: =(($F43/(1-J$9))) -> 338.775 | K43: =(($F43/(1-$K$9))) -> 416.95385 | L43: =(($F43/(1-L$9))) -> 542.04
B44: Water Flow Cartridge Kit, 1.59 GPM, Brass, 3/4” NPT | C44: 1 | D44: K000953153 | E44: =VLOOKUP(D44,Sheet1!B:C, 2, FALSE) -> K09530006VXWCB9 | F44: 114.8635 | G44: ='March 2025'!F44 -> 1310 | H44: =G44*$H$5 -> 484.7 | I44: =((H44-F44)/H44) -> 0.76302146 | J44: =(($F44/(1-J$9))) -> 287.15875 | K44: =(($F44/(1-$K$9))) -> 353.42615 | L44: =(($F44/(1-L$9))) -> 459.454
...

Sheet March 2025
B1: Victaulic Vortex® System Product List Price Effective March 1st, 2025
B2: United States
G4: Multiplier:
B5: NOTE: Please add information to the cells shaded in | C5: GREEN. | G5: 0.37
B7: Option Style | C7: Shipping Weight | D7: Part Code | E7: Cost (USD) | F7: List Price (USD) | G7: Extended Price | H7: GM % | I7: 60% Margin Sell | J7: 67.5% Margin Sell | K7: 75% Margin Sell
B9: Emitters | I9: 0.6 | J9: 0.675 | K9: 0.75
B10: 1/8" Emitters
B11: 1/8” Emitter, 954 cavity foil, standard, PVDF, 3/8” FPT, 1/8” FPT | C11: 1 | D11: S003953105 | E11: 195.71 | F11: =CEILING((Updated!F11*1.06),0.5) -> 2986.5 | G11: =F11*$G$5 -> 1105.005 | H11: =((G11-E11)/G11) -> 0.82288768 | I11: =(($E11/(1-$I9))) -> 489.275 | J11: =(($E11/(1-$J$9))) -> 602.18462 | K11: =(($E11/(1-$K9))) -> 782.84
B12: 1/8” Emitter, 953 dome foil, standard, stainless, 3/8” FPT, 1/8” FPT | C12: 1 | D12: S00195310X | E12: 171.534 | F12: =CEILING((Updated!F12*1.06),0.5) -> 2874.5 | G12: =F12*$G$5 -> 1063.565 | H12: =((G12-E12)/G12) -> 0.8387179 | I12: =(($E12/(1-$I$9))) -> 428.835 | J12: =(($E12/(1-$J$9))) -> 527.79692 | K12: =(($E12/(1-$K$9))) -> 686.136
B13: 1/4" Emitters
B14: 1/4” Emitter, 953 dome foil, standard, stainless, 3/4” MPT, 1/4” FPT | C14: 1 | D14: S002953X02 | E14: 160.1174 | F14: =CEILING((Updated!F14*1.06),0.5) -> 3333 | G14: =F14*$G$5 -> 1233.21 | H14: =((G14-E14)/G14) -> 0.8701621 | I14: =(($E14/(1-I$9))) -> 400.2935 | J14: =(($E14/(1-$J$9))) -> 492.66892 | K14: =(($E14/(1-K$9))) -> 640.4696
B15: 1/4” Emitter, 954 cavity foil, standard, PVDF, 3/8” FPT, 1/8” FPT | C15: 1 | D15: S003953170 | E15: 241.4136 | F15: =CEILING((Updated!F15*1.06),0.5) -> 2985.5 | G15: =F15*$G$5 -> 1104.635 | H15: =((G15-E15)/G15) -> 0.78145396 | I15: =(($E15/(1-$I$9))) -> 603.534 | J15: =(($E15/(1-$J$9))) -> 742.81108 | K15: =(($E15/(1-$K$9))) -> 965.6544
B16: 3/8" Emitters
B17: 3/8” Emitter, 953 dome foil, escutcheon, stainless, 3/4” FPT, 1/4” FPT | C17: 1 | D17: S003953032 | E17: 52.3201 | F17: =CEILING((Updated!F17*1.06),0.5) -> 1332.5 | G17: =F17*$G$5 -> 493.025 | H17: =((G17-E17)/G17) -> 0.89387942 | I17: =(($E17/(1-I$9))) -> 130.80025 | J17: =(($E17/(1-$J$9))) -> 160.98492 | K17: =(($E17/(1-K$9))) -> 209.2804
B18: 3/8” Emitter, 953 dome foil, standard, stainless, 3/4” FPT, 1/4” FPT | C18: 1 | D18: S003953034 | E18: 34.5438 | F18: =CEILING((Updated!F18*1.06),0.5) -> 1262.5 | G18: =F18*$G$5 -> 467.125 | H18: =((G18-E18)/G18) -> 0.9260502 | I18: =(($E18/(1-I$9))) -> 86.3595 | J18: =(($E18/(1-$J$9))) -> 106.28862 | K18: =(($E18/(1-K$9))) -> 138.1752
B19: 3/8” Emitter, 954 cavity foil, escutcheon, stainless, 3/4” FPT, 1/4” FPT | C19: 1 | D19: S003953031 | E19: 51.85424 | F19: =CEILING((Updated!F19*1.06),0.5) -> 1332.5 | G19: =F19*$G$5 -> 493.025 | H19: =((G19-E19)/G19) -> 0.89482432 | I19: =(($E19/(1-I$9))) -> 129.6356 | J19: =(($E19/(1-$J$9))) -> 159.55151 | K19: =(($E19/(1-K$9))) -> 207.41696
B20: 3/8” Emitter, 954 cavity foil, standard, stainless, 3/4” FPT, 1/4” FPT | C20: 1 | D20: S003953033 | E20: 34.07794 | F20: =CEILING((Updated!F20*1.06),0.5) -> 1262.5 | G20: =F20*$G$5 -> 467.125 | H20: =((G20-E20)/G20) -> 0.92704749 | I20: =(($E20/(1-I$9))) -> 85.19485 | J20: =(($E20/(1-$J$9))) -> 104.8552 | K20: =(($E20/(1-K$9))) -> 136.31176
B21: 1/2" Emitters
B22: 1/2” Emitter, 953 dome foil, standard, brass, 3/4” MPT, 1/4” FPT | C22: 1 | D22: S006953400 | E22: 102.34866 | F22: =CEILING((Updated!F22*1.06),0.5) -> 1262.5 | G22: =F22*$G$5 -> 467.125 | H22: =((G22-E22)/G22) -> 0.78089663 | I22: =(($E22/(1-I$9))) -> 255.87165 | J22: =(($E22/(1-$J$9))) -> 314.91895 | K22: =(($E22/(1-K$9))) -> 409.39464
B23: 1/2” Emitter, 953 dome foil, standard, PVDF, 3/4” MPT, 1/4” FPT | C23: 1 | D23: S006953406 | E23: 230.5925 | F23: =CEILING((Updated!F23*1.06),0.5) -> 2345 | G23: =F23*$G$5 -> 867.65 | H23: =((G23-E23)/G23) -> 0.73423327 | I23: =(($E23/(1-I$9))) -> 576.48125 | J23: =(($E23/(1-$J$9))) -> 709.51538 | K23: =(($E23/(1-K$9))) -> 922.37
B24: 1/2” Emitter, 953 dome foil, escutcheon, stainless, 3/4” FPT, 1/4” FPT | C24: 1 | D24: S004953511 | E24: 60.22 | F24: =CEILING((Updated!F24*1.06),0.5) -> 1332.5 | G24: =F24*$G$5 -> 493.025 | H24: =((G24-E24)/G24) -> 0.87785609 | I24: =(($E24/(1-I$9))) -> 150.55 | J24: =(($E24/(1-$J$9))) -> 185.29231 | K24: =(($E24/(1-K$9))) -> 240.88
B25: 1/2” Emitter, 953 dome foil, standard, stainless, 3/4” FPT, 1/4” FPT | C25: 1 | D25: S004953513 | E25: 35.2038 | F25: =CEILING((Updated!F25*1.06),0.5) -> 1759 | G25: =F25*$G$5 -> 650.83 | H25: =((G25-E25)/G25) -> 0.94590938 | I25: =(($E25/(1-I$9))) -> 88.0095 | J25: =(($E25/(1-$J$9))) -> 108.31938 | K25: =(($E25/(1-K$9))) -> 140.8152
B26: 5/8" Emitters
B27: 5/8” Emitter, 954 cavity foil, standard, PVDF, 3/4” FPT, 1/4" FPT | C27: 1 | D27: S006953503 | E27: 193.3368 | F27: =CEILING((Updated!F27*1.06),0.5) -> 2986.5 | G27: =F27*$G$5 -> 1105.005 | H27: =((G27-E27)/G27) -> 0.82503536 | I27: =(($E27/(1-I$9))) -> 483.342 | J27: =(($E27/(1-$J$9))) -> 594.88246 | K27: =(($E27/(1-K$9))) -> 773.3472
B28: 5/8” Emitter, 954 cavity foil, escutcheon, stainless, 3/4” FPT, 1/4” FPT | C28: 1 | D28: S006953512 | E28: 50.4801 | F28: =CEILING((Updated!F28*1.06),0.5) -> 1332.5 | G28: =F28*$G$5 -> 493.025 | H28: =((G28-E28)/G28) -> 0.89761148 | I28: =(($E28/(1-I$9))) -> 126.20025 | J28: =(($E28/(1-$J$9))) -> 155.32338 | K28: =(($E28/(1-K$9))) -> 201.9204
B29: 5/8” Emitter, 954 cavity foil, standard, stainless, 3/4” FPT, 1/4” FPT | C29: 1 | D29: S006953514 | E29: 32.7038 | F29: =CEILING((Updated!F29*1.06),0.5) -> 1262.5 | G29: =F29*$G$5 -> 467.125 | H29: =((G29-E29)/G29) -> 0.92998919 | I29: =(($E29/(1-I$9))) -> 81.7595 | J29: =(($E29/(1-$J$9))) -> 100.62708 | K29: =(($E29/(1-K$9))) -> 130.8152
B30: 1" Emitters
B31: 1” Emitter, 953/954 dome foil, escutcheon, stainless, 1” FPT, 1/8” FPT | C31: 1 | D31: S010953511 | E31: 68.4904 | F31: =CEILING((Updated!F31*1.06),0.5) -> 2316.5 | G31: =F31*$G$5 -> 857.105 | H31: =((G31-E31)/G31) -> 0.920091 | I31: =(($E31/(1-I$9))) -> 171.226 | J31: =(($E31/(1-$J$9))) -> 210.73969 | K31: =(($E31/(1-K$9))) -> 273.9616
B33: Water Flow Kits (Strainer, Flow Cartridge, Emitter Trim Kit)
B34: Water Flow Cartridge Kit, .13 GPM, Brass, 3/4” NPT | C34: 1 | D34: K000953013 | E34: 103.42 | F34: =CEILING((Updated!F34*1.06),0.5) -> 1310 | G34: =F34*$G$5 -> 484.7 | H34: =((G34-E34)/G34) -> 0.78663091 | I34: =(($E34/(1-I$9))) -> 258.55 | J34: =(($E34/(1-$J$9))) -> 318.21538 | K34: =(($E34/(1-K$9))) -> 413.68
B35: Water Flow Cartridge Kit, .13 GPM, Stainless, 3/4” NPT | C35: 1 | D35: K000953X13 | E35: 133.39 | F35: =CEILING((Updated!F35*1.06),0.5) -> 1556.5 | G35: =F35*$G$5 -> 575.905 | H35: =((G35-E35)/G35) -> 0.76838194 | I35: =(($E35/(1-I$9))) -> 333.475 | J35: =(($E35/(1-$J$9))) -> 410.43077 | K35: =(($E35/(1-K$9))) -> 533.56
B36: Water Flow Cartridge Kit, .26 GPM, Brass, 3/4” NPT | C36: 1 | D36: K000953026 | E36: 109.44 | F36: =CEILING((Updated!F36*1.06),0.5) -> 1310 | G36: =F36*$G$5 -> 484.7 | H36: =((G36-E36)/G36) -> 0.77421085 | I36: =(($E36/(1-I$9))) -> 273.6 | J36: =(($E36/(1-$J$9))) -> 336.73846 | K36: =(($E36/(1-K$9))) -> 437.76
B37: Water Flow Cartridge Kit, .26 GPM, Stainless, 3/4” NPT | C37: 1 | D37: K000953X26 | E37: 133.39 | F37: =CEILING((Updated!F37*1.06),0.5) -> 1556.5 | G37: =F37*$G$5 -> 575.905 | H37: =((G37-E37)/G37) -> 0.76838194 | I37: =(($E37/(1-I$9))) -> 333.475 | J37: =(($E37/(1-$J$9))) -> 410.43077 | K37: =(($E37/(1-K$9))) -> 533.56
B38: Water Flow Cartridge Kit, .53 GPM, Brass, 3/4” NPT | C38: 1 | D38: K000953053 | E38: 103.42 | F38: =CEILING((Updated!F38*1.06),0.5) -> 1310 | G38: =F38*$G$5 -> 484.7 | H38: =((G38-E38)/G38) -> 0.78663091 | I38: =(($E38/(1-I$9))) -> 258.55 | J38: =(($E38/(1-$J$9))) -> 318.21538 | K38: =(($E38/(1-K$9))) -> 413.68
B39: Water Flow Cartridge Kit, .53 GPM, Stainless, 3/4” NPT | C39: 1 | D39: K000953X53 | E39: 135.51 | F39: =CEILING((Updated!F39*1.06),0.5) -> 1556.5 | G39: =F39*$G$5 -> 575.905 | H39: =((G39-E39)/G39) -> 0.76470078 | I39: =(($E39/(1-I$9))) -> 338.775 | J39: =(($E39/(1-$J$9))) -> 416.95385 | K39: =(($E39/(1-K$9))) -> 542.04
B40: Water Flow Cartridge Kit, .79 GPM, Brass, 3/4” NPT | C40: 1 | D40: K000953079 | E40: 103.42 | F40: =CEILING((Updated!F40*1.06),0.5) -> 1310 | G40: =F40*$G$5 -> 484.7 | H40: =((G40-E40)/G40) -> 0.78663091 | I40: =(($E40/(1-I$9))) -> 258.55 | J40: =(($E40/(1-$J$9))) -> 318.21538 | K40: =(($E40/(1-K$9))) -> 413.68
B41: Water Flow Cartridge Kit, .79 GPM, Stainless, 3/4” NPT | C41: 1 | D41: K000953X79 | E41: 135.51 | F41: =CEILING((Updated!F41*1.06),0.5) -> 1556.5 | G41: =F41*$G$5 -> 575.905 | H41: =((G41-E41)/G41) -> 0.76470078 | I41: =(($E41/(1-I$9))) -> 338.775 | J41: =(($E41/(1-$J$9))) -> 416.95385 | K41: =(($E41/(1-K$9))) -> 542.04
B42: Water Flow Cartridge Kit, 1.06 GPM, Brass, 3/4” NPT | C42: 1 | D42: K000953106 | E42: 103.42 | F42: =CEILING((Updated!F42*1.06),0.5) -> 1310 | G42: =F42*$G$5 -> 484.7 | H42: =((G42-E42)/G42) -> 0.78663091 | I42: =(($E42/(1-I$9))) -> 258.55 | J42: =(($E42/(1-$J$9))) -> 318.21538 | K42: =(($E42/(1-K$9))) -> 413.68
B43: Water Flow Cartridge Kit, 1.06 GPM, Stainless, 3/4” NPT | C43: 1 | D43: K000953X06 | E43: 135.51 | F43: =CEILING((Updated!F43*1.06),0.5) -> 1556.5 | G43: =F43*$G$5 -> 575.905 | H43: =((G43-E43)/G43) -> 0.76470078 | I43: =(($E43/(1-I$9))) -> 338.775 | J43: =(($E43/(1-$J$9))) -> 416.95385 | K43: =(($E43/(1-K$9))) -> 542.04
B44: Water Flow Cartridge Kit, 1.59 GPM, Brass, 3/4” NPT | C44: 1 | D44: K000953153 | E44: 114.8635 | F44: =CEILING((Updated!F44*1.06),0.5) -> 1310 | G44: =F44*$G$5 -> 484.7 | H44: =((G44-E44)/G44) -> 0.76302146 | I44: =(($E44/(1-I$9))) -> 287.15875 | J44: =(($E44/(1-$J$9))) -> 353.42615 | K44: =(($E44/(1-K$9))) -> 459.454
...

Sheet Updated
B1: Victaulic Vortex® System Product List Price Effective May 2024
B2: United States
G4: Multiplier:
B5: NOTE: Please add information to the cells shaded in | C5: GREEN. | G5: 0.37
B7: Option Style | C7: Shipping Weight | D7: Part Code | E7: Cost (USD) | F7: List Price (USD) | G7: Extended Price | H7: GM % | I7: 60% Margin Sell | J7: 67.5% Margin Sell | K7: 75% Margin Sell
B9: Emitters | I9: 0.6 | J9: 0.675 | K9: 0.75
B10: 1/8" Emitters
B11: 1/8” Emitter, 954 cavity foil, standard, PVDF, 3/8” FPT, 1/8” FPT | C11: 1 | D11: S003953105 | E11: 195.71 | F11: =CEILING((Master!F13*1.06),0.5) -> 2817 | G11: =F11*$G$5 -> 1042.29 | H11: =((G11-E11)/G11) -> 0.81223076 | I11: =(($E11/(1-$I9))) -> 489.275 | J11: =(($E11/(1-$J$9))) -> 602.18462 | K11: =(($E11/(1-$K9))) -> 782.84
B12: 1/8” Emitter, 953 dome foil, standard, stainless, 3/8” FPT, 1/8” FPT | C12: 1 | D12: S00195310X | E12: 171.534 | F12: =CEILING((Master!F14*1.06),0.5) -> 2711.5 | G12: =F12*$G$5 -> 1003.255 | H12: =((G12-E12)/G12) -> 0.82902253 | I12: =(($E12/(1-$I$9))) -> 428.835 | J12: =(($E12/(1-$J$9))) -> 527.79692 | K12: =(($E12/(1-$K$9))) -> 686.136
B13: 1/4" Emitters
B14: 1/4” Emitter, 953 dome foil, standard, stainless, 3/4” MPT, 1/4” FPT | C14: 1 | D14: S002953X02 | E14: 160.1174 | F14: =CEILING((Master!F16*1.06),0.5) -> 3144 | G14: =F14*$G$5 -> 1163.28 | H14: =((G14-E14)/G14) -> 0.86235696 | I14: =(($E14/(1-I$9))) -> 400.2935 | J14: =(($E14/(1-$J$9))) -> 492.66892 | K14: =(($E14/(1-K$9))) -> 640.4696
B15: 1/4” Emitter, 954 cavity foil, standard, PVDF, 3/8” FPT, 1/8” FPT | C15: 1 | D15: S003953170 | E15: 241.4136 | F15: =CEILING((Master!F18*1.06),0.5) -> 2816.5 | G15: =F15*$G$5 -> 1042.105 | H15: =((G15-E15)/G15) -> 0.76834043 | I15: =(($E15/(1-$I$9))) -> 603.534 | J15: =(($E15/(1-$J$9))) -> 742.81108 | K15: =(($E15/(1-$K$9))) -> 965.6544
B16: 3/8" Emitters
B17: 3/8” Emitter, 953 dome foil, escutcheon, stainless, 3/4” FPT, 1/4” FPT | C17: 1 | D17: S003953032 | E17: 52.3201 | F17: 1257 | G17: =F17*$G$5 -> 465.09 | H17: =((G17-E17)/G17) -> 0.88750543 | I17: =(($E17/(1-I$9))) -> 130.80025 | J17: =(($E17/(1-$J$9))) -> 160.98492 | K17: =(($E17/(1-K$9))) -> 209.2804
B18: 3/8” Emitter, 953 dome foil, standard, stainless, 3/4” FPT, 1/4” FPT | C18: 1 | D18: S003953034 | E18: 34.5438 | F18: 1191 | G18: =F18*$G$5 -> 440.67 | H18: =((G18-E18)/G18) -> 0.92161073 | I18: =(($E18/(1-I$9))) -> 86.3595 | J18: =(($E18/(1-$J$9))) -> 106.28862 | K18: =(($E18/(1-K$9))) -> 138.1752
B19: 3/8” Emitter, 954 cavity foil, escutcheon, stainless, 3/4” FPT, 1/4” FPT | C19: 1 | D19: S003953031 | E19: 51.85424 | F19: 1257 | G19: =F19*$G$5 -> 465.09 | H19: =((G19-E19)/G19) -> 0.88850708 | I19: =(($E19/(1-I$9))) -> 129.6356 | J19: =(($E19/(1-$J$9))) -> 159.55151 | K19: =(($E19/(1-K$9))) -> 207.41696
B20: 3/8” Emitter, 954 cavity foil, standard, stainless, 3/4” FPT, 1/4” FPT | C20: 1 | D20: S003953033 | E20: 34.07794 | F20: 1191 | G20: =F20*$G$5 -> 440.67 | H20: =((G20-E20)/G20) -> 0.92266789 | I20: =(($E20/(1-I$9))) -> 85.19485 | J20: =(($E20/(1-$J$9))) -> 104.8552 | K20: =(($E20/(1-K$9))) -> 136.31176
B21: 1/2" Emitters
B22: 1/2” Emitter, 953 dome foil, standard, brass, 3/4” MPT, 1/4” FPT | C22: 1 | D22: S006953400 | E22: 102.34866 | F22: =CEILING((Master!F33*1.06),0.5) -> 1191 | G22: =F22*$G$5 -> 440.67 | H22: =((G22-E22)/G22) -> 0.76774307 | I22: =(($E22/(1-I$9))) -> 255.87165 | J22: =(($E22/(1-$J$9))) -> 314.91895 | K22: =(($E22/(1-K$9))) -> 409.39464
B23: 1/2” Emitter, 953 dome foil, standard, PVDF, 3/4” MPT, 1/4” FPT | C23: 1 | D23: S006953406 | E23: 230.5925 | F23: =CEILING((Master!F35*1.06),0.5) -> 2212 | G23: =F23*$G$5 -> 818.44 | H23: =((G23-E23)/G23) -> 0.71825363 | I23: =(($E23/(1-I$9))) -> 576.48125 | J23: =(($E23/(1-$J$9))) -> 709.51538 | K23: =(($E23/(1-K$9))) -> 922.37
B24: 1/2” Emitter, 953 dome foil, escutcheon, stainless, 3/4” FPT, 1/4” FPT | C24: 1 | D24: S004953511 | E24: 60.22 | F24: 1257 | G24: =F24*$G$5 -> 465.09 | H24: =((G24-E24)/G24) -> 0.87051968 | I24: =(($E24/(1-I$9))) -> 150.55 | J24: =(($E24/(1-$J$9))) -> 185.29231 | K24: =(($E24/(1-K$9))) -> 240.88
B25: 1/2” Emitter, 953 dome foil, standard, stainless, 3/4” FPT, 1/4” FPT | C25: 1 | D25: S004953513 | E25: 35.2038 | F25: 1659 | G25: =F25*$G$5 -> 613.83 | H25: =((G25-E25)/G25) -> 0.94264894 | I25: =(($E25/(1-I$9))) -> 88.0095 | J25: =(($E25/(1-$J$9))) -> 108.31938 | K25: =(($E25/(1-K$9))) -> 140.8152
B26: 5/8" Emitters
B27: 5/8” Emitter, 954 cavity foil, standard, PVDF, 3/4” FPT, 1/4" FPT | C27: 1 | D27: S006953503 | E27: 193.3368 | F27: =CEILING((Master!F41*1.06),0.5) -> 2817 | G27: =F27*$G$5 -> 1042.29 | H27: =((G27-E27)/G27) -> 0.81450767 | I27: =(($E27/(1-I$9))) -> 483.342 | J27: =(($E27/(1-$J$9))) -> 594.88246 | K27: =(($E27/(1-K$9))) -> 773.3472
B28: 5/8” Emitter, 954 cavity foil, escutcheon, stainless, 3/4” FPT, 1/4” FPT | C28: 1 | D28: S006953512 | E28: 50.4801 | F28: 1257 | G28: =F28*$G$5 -> 465.09 | H28: =((G28-E28)/G28) -> 0.89146165 | I28: =(($E28/(1-I$9))) -> 126.20025 | J28: =(($E28/(1-$J$9))) -> 155.32338 | K28: =(($E28/(1-K$9))) -> 201.9204
B29: 5/8” Emitter, 954 cavity foil, standard, stainless, 3/4” FPT, 1/4” FPT | C29: 1 | D29: S006953514 | E29: 32.7038 | F29: 1191 | G29: =F29*$G$5 -> 440.67 | H29: =((G29-E29)/G29) -> 0.92578619 | I29: =(($E29/(1-I$9))) -> 81.7595 | J29: =(($E29/(1-$J$9))) -> 100.62708 | K29: =(($E29/(1-K$9))) -> 130.8152
B30: 1" Emitters
B31: 1” Emitter, 953/954 dome foil, escutcheon, stainless, 1” FPT, 1/8” FPT | C31: 1 | D31: S010953511 | E31: 68.4904 | F31: 2185 | G31: =F31*$G$5 -> 808.45 | H31: =((G31-E31)/G31) -> 0.91528184 | I31: =(($E31/(1-I$9))) -> 171.226 | J31: =(($E31/(1-$J$9))) -> 210.73969 | K31: =(($E31/(1-K$9))) -> 273.9616
B33: Water Flow Kits (Strainer, Flow Cartridge, Emitter Trim Kit)
B34: Water Flow Cartridge Kit, .13 GPM, Brass, 3/4” NPT | C34: 1 | D34: K000953013 | E34: 103.42 | F34: =CEILING((Master!F51*1.06),0.5) -> 1235.5 | G34: =F34*$G$5 -> 457.135 | H34: =((G34-E34)/G34) -> 0.77376486 | I34: =(($E34/(1-I$9))) -> 258.55 | J34: =(($E34/(1-$J$9))) -> 318.21538 | K34: =(($E34/(1-K$9))) -> 413.68
B35: Water Flow Cartridge Kit, .13 GPM, Stainless, 3/4” NPT | C35: 1 | D35: K000953X13 | E35: 133.39 | F35: =CEILING((Master!F52*1.06),0.5) -> 1468 | G35: =F35*$G$5 -> 543.16 | H35: =((G35-E35)/G35) -> 0.75441859 | I35: =(($E35/(1-I$9))) -> 333.475 | J35: =(($E35/(1-$J$9))) -> 410.43077 | K35: =(($E35/(1-K$9))) -> 533.56
B36: Water Flow Cartridge Kit, .26 GPM, Brass, 3/4” NPT | C36: 1 | D36: K000953026 | E36: 109.44 | F36: =CEILING((Master!F53*1.06),0.5) -> 1235.5 | G36: =F36*$G$5 -> 457.135 | H36: =((G36-E36)/G36) -> 0.76059589 | I36: =(($E36/(1-I$9))) -> 273.6 | J36: =(($E36/(1-$J$9))) -> 336.73846 | K36: =(($E36/(1-K$9))) -> 437.76
B37: Water Flow Cartridge Kit, .26 GPM, Stainless, 3/4” NPT | C37: 1 | D37: K000953X26 | E37: 133.39 | F37: =CEILING((Master!F54*1.06),0.5) -> 1468 | G37: =F37*$G$5 -> 543.16 | H37: =((G37-E37)/G37) -> 0.75441859 | I37: =(($E37/(1-I$9))) -> 333.475 | J37: =(($E37/(1-$J$9))) -> 410.43077 | K37: =(($E37/(1-K$9))) -> 533.56
B38: Water Flow Cartridge Kit, .53 GPM, Brass, 3/4” NPT | C38: 1 | D38: K000953053 | E38: 103.42 | F38: =CEILING((Master!F55*1.06),0.5) -> 1235.5 | G38: =F38*$G$5 -> 457.135 | H38: =((G38-E38)/G38) -> 0.77376486 | I38: =(($E38/(1-I$9))) -> 258.55 | J38: =(($E38/(1-$J$9))) -> 318.21538 | K38: =(($E38/(1-K$9))) -> 413.68
B39: Water Flow Cartridge Kit, .53 GPM, Stainless, 3/4” NPT | C39: 1 | D39: K000953X53 | E39: 135.51 | F39: =CEILING((Master!F56*1.06),0.5) -> 1468 | G39: =F39*$G$5 -> 543.16 | H39: =((G39-E39)/G39) -> 0.7505155 | I39: =(($E39/(1-I$9))) -> 338.775 | J39: =(($E39/(1-$J$9))) -> 416.95385 | K39: =(($E39/(1-K$9))) -> 542.04
B40: Water Flow Cartridge Kit, .79 GPM, Brass, 3/4” NPT | C40: 1 | D40: K000953079 | E40: 103.42 | F40: =CEILING((Master!F57*1.06),0.5) -> 1235.5 | G40: =F40*$G$5 -> 457.135 | H40: =((G40-E40)/G40) -> 0.77376486 | I40: =(($E40/(1-I$9))) -> 258.55 | J40: =(($E40/(1-$J$9))) -> 318.21538 | K40: =(($E40/(1-K$9))) -> 413.68
B41: Water Flow Cartridge Kit, .79 GPM, Stainless, 3/4” NPT | C41: 1 | D41: K000953X79 | E41: 135.51 | F41: =CEILING((Master!F58*1.06),0.5) -> 1468 | G41: =F41*$G$5 -> 543.16 | H41: =((G41-E41)/G41) -> 0.7505155 | I41: =(($E41/(1-I$9))) -> 338.775 | J41: =(($E41/(1-$J$9))) -> 416.95385 | K41: =(($E41/(1-K$9))) -> 542.04
B42: Water Flow Cartridge Kit, 1.06 GPM, Brass, 3/4” NPT | C42: 1 | D42: K000953106 | E42: 103.42 | F42: =CEILING((Master!F59*1.06),0.5) -> 1235.5 | G42: =F42*$G$5 -> 457.135 | H42: =((G42-E42)/G42) -> 0.77376486 | I42: =(($E42/(1-I$9))) -> 258.55 | J42: =(($E42/(1-$J$9))) -> 318.21538 | K42: =(($E42/(1-K$9))) -> 413.68
B43: Water Flow Cartridge Kit, 1.06 GPM, Stainless, 3/4” NPT | C43: 1 | D43: K000953X06 | E43: 135.51 | F43: =CEILING((Master!F60*1.06),0.5) -> 1468 | G43: =F43*$G$5 -> 543.16 | H43: =((G43-E43)/G43) -> 0.7505155 | I43: =(($E43/(1-I$9))) -> 338.775 | J43: =(($E43/(1-$J$9))) -> 416.95385 | K43: =(($E43/(1-K$9))) -> 542.04
B44: Water Flow Cartridge Kit, 1.59 GPM, Brass, 3/4” NPT | C44: 1 | D44: K000953153 | E44: 114.8635 | F44: 1235.5 | G44: =F44*$G$5 -> 457.135 | H44: =((G44-E44)/G44) -> 0.74873178 | I44: =(($E44/(1-I$9))) -> 287.15875 | J44: =(($E44/(1-$J$9))) -> 353.42615 | K44: =(($E44/(1-K$9))) -> 459.454
...

Sheet Master
B1: Victaulic Vortex® System Product List Price Effective 3 April 2023
B2: United States
G4: Multiplier:
B5: NOTE: Please add information to the cells shaded in | C5: GREEN. | G5: 0.37
N6: =SUM(N11:N245) -> 49919.66
B7: Option Style | C7: Shipping Weight | D7: Part Code | E7: Cost (USD) | F7: List Price (USD) | G7: Extended Price | H7: GM % | I7: 60% Margin Sell | J7: 75% Margin Sell | K7: Requested to be removed | M7: QTY | N7: NET
B9: Emitters | O9: Applied Formulas
B10: 1/8" Emitters | O10: IPROD | P10: PL23
B11: 1/8” Emitter, 953 dome foil, standard, brass, 3/8” FPT, 1/8” FPT | C11: 1 | D11: S001953100 | E11: 162.334 | F11: 2019 | G11: =F11*$G$5 -> 747.03 | H11: =((G11-E11)/G11) -> 0.78269414 | I11: =(5*E11)/2 -> 405.835 | J11: =(4*E11) -> 649.336 | K11: Yes | O11: P480955228 | P11: 617
B12: 1/8” Emitter, 954 cavity foil, standard, brass, 3/8” FPT, 1/8” FPT | C12: 1 | D12: S001953101 | E12: 142.334 | F12: 2018 | G12: =F12*$G$5 -> 746.66 | H12: =((G12-E12)/G12) -> 0.80937241 | I12: =(5*E12)/2 -> 355.835 | J12: =(4*E12) -> 569.336 | K12: Yes | O12: S000950HCW | P12: 4871
B13: 1/8” Emitter, 953 cavity foil, standard, PVDF, 3/8” FPT, 1/8” FPT | C13: 1 | D13: S003953105 | E13: 195.7136 | F13: 2657.5 | G13: =F13*$G$5 -> 983.275 | H13: =((G13-E13)/G13) -> 0.80095741 | I13: =(5*E13)/2 -> 489.284 | J13: =(4*E13) -> 782.8544 | O13: P000950PAL | P13: 6
B14: 1/8” Emitter, 953 dome foil, standard, stainless, 3/8” FPT, 1/8” FPT | C14: 1 | D14: S00195310X | E14: 171.534 | F14: 2558 | G14: =F14*$G$5 -> 946.46 | H14: =((G14-E14)/G14) -> 0.81876255 | I14: =(5*E14)/2 -> 428.835 | J14: =(4*E14) -> 686.136 | O14: S001953101 | P14: 2018
B15: 1/4" Emitters | I15: =(5*E15)/2 -> 0 | J15: =(4*E15) -> 0 | O15: S003953170 | P15: 2657
B16: 1/4” Emitter, 953 dome foil, standard, stainless, 3/4” MPT, 1/4” FPT | C16: 1 | D16: S002953X02 | E16: 160.1174 | F16: 2966 | G16: =F16*$G$5 -> 1097.42 | H16: =((G16-E16)/G16) -> 0.85409652 | I16: =(5*E16)/2 -> 400.2935 | J16: =(4*E16) -> 640.4696 | O16: S00495350A | P16: 3383
B17: 1/4” Emitter, 953 dome foil, standard, brass, 3/4” MPT, 1/4” FPT | C17: 1 | D17: S002953101 | E17: 111.1814 | F17: 1969.5 | G17: =F17*$G$5 -> 728.715 | H17: =((G17-E17)/G17) -> 0.84742814 | I17: =(5*E17)/2 -> 277.9535 | J17: =(4*E17) -> 444.7256 | K17: Yes | O17: K800950003 | P17: 5965.5
B18: 1/4” Emitter, 954 cavity foil, standard, PVDF, 3/8” FPT, 1/8” FPT | C18: 1 | D18: S003953170 | E18: 241.4136 | F18: 2657 | G18: =F18*$G$5 -> 983.09 | H18: =((G18-E18)/G18) -> 0.75443388 | I18: =(5*E18)/2 -> 603.534 | J18: =(4*E18) -> 965.6544 | O18: K800950104 | P18: 6721.5
B19: 1/4” Emitter, 954 cavity foil, standard, brass, 3/4” MPT, 1/4” FPT | C19: 1 | D19: S002953100 | E19: 111.1814 | F19: 1968.5 | G19: =F19*$G$5 -> 728.345 | H19: =((G19-E19)/G19) -> 0.84735064 | I19: =(5*E19)/2 -> 277.9535 | J19: =(4*E19) -> 444.7256 | K19: Yes | O19: P00495000U | P19: 820.5
B20: 1/4” Emitter, 954 cavity foil, standard, stainless, 3/4” MPT, 1/4” FPT | C20: 1 | D20: S002953X01 | E20: 159.8124 | F20: 2966 | G20: =F20*$G$5 -> 1097.42 | H20: =((G20-E20)/G20) -> 0.85437444 | I20: =(5*E20)/2 -> 399.531 | J20: =(4*E20) -> 639.2496 | K20: Yes | O20: K000950KIT | P20: 173.5
B21: 1/4” Emitter, 954 cavity foil, escutcheon, stainless, 3/4” FPT, 1/4” FPT | C21: 1 | D21: S00295310A | E21: 446.1574 | F21: 5074 | G21: =F21*$G$5 -> 1877.38 | H21: =((G21-E21)/G21) -> 0.76235104 | I21: =(5*E21)/2 -> 1115.3935 | J21: =(4*E21) -> 1784.6296 | K21: Yes | O21: K490950008 | P21: 7510.5
B22: 3/8" Emitters | I22: =(5*E22)/2 -> 0 | J22: =(4*E22) -> 0 | O22: K800950002 | P22: 5264.5
B23: 3/8” Emitter, 953 dome foil, standard, stainless, 3/4” MPT, 1/4” FPT | C23: 1 | D23: S003953X30 | E23: 159.14672 | F23: 2374 | G23: =F23*$G$5 -> 878.38 | H23: =((G23-E23)/G23) -> 0.81881791 | I23: =(5*E23)/2 -> 397.8668 | J23: =(4*E23) -> 636.58688 | K23: Yes | O23: K800950004 | P23: 5374.5
B24: 3/8” Emitter, 953 dome foil, standard, brass, 3/4” MPT, 1/4” FPT | C24: 1 | D24: S003953131 | E24: 98.51572 | F24: 1477.5 | G24: =F24*$G$5 -> 546.675 | H24: =((G24-E24)/G24) -> 0.81979106 | I24: =(5*E24)/2 -> 246.2893 | J24: =(4*E24) -> 394.06288 | K24: Yes | O24: K800950006 | P24: 6590.5
B25: 3/8” Emitter, 954 cavity foil, standard, brass, 3/4” MPT, 1/4” FPT | C25: 1 | D25: S003953130 | E25: 98.46572 | F25: 1477.5 | G25: =F25*$G$5 -> 546.675 | H25: =((G25-E25)/G25) -> 0.81988253 | I25: =(5*E25)/2 -> 246.1643 | J25: =(4*E25) -> 393.86288 | K25: Yes | O25: K800950008 | P25: 7471.5
B26: 3/8” Emitter, 954 cavity foil, escutcheon, stainless, 3/4” FPT, 1/4” FPT | C26: 1.5 | D26: S00395310A | E26: 132.80184 | F26: 5074 | G26: =F26*$G$5 -> 1877.38 | H26: =((G26-E26)/G26) -> 0.92926214 | I26: =(5*E26)/2 -> 332.0046 | J26: =(4*E26) -> 531.20736 | K26: Yes | O26: K800950012 | P26: 9143
A27: NEW | B27: 3/8” Emitter, 953 dome foil, escutcheon, stainless, 3/4” FPT, 1/4” FPT | D27: S003953032 | E27: 52.3201 | F27: 2374 | G27: =F27*$G$5 -> 878.38 | H27: =((G27-E27)/G27) -> 0.94043569 | I27: =(5*E27)/2 -> 130.80025 | J27: =(4*E27) -> 209.2804 | O27: K800950106 | P27: 8105
A28: NEW | B28: 3/8” Emitter, 953 dome foil, standard, stainless, 3/4” FPT, 1/4” FPT | D28: S003953034 | E28: 34.5438 | F28: 1447.5 | G28: =F28*$G$5 -> 535.575 | H28: =((G28-E28)/G28) -> 0.93550147 | I28: =(5*E28)/2 -> 86.3595 | J28: =(4*E28) -> 138.1752 | O28: K000953X06 | P28: 1384.5
A29: NEW | B29: 3/8” Emitter, 954 cavity foil, escutcheon, stainless, 3/4” FPT, 1/4” FPT | D29: S003953031 | E29: 51.85424 | F29: 2374 | G29: =F29*$G$5 -> 878.38 | H29: =((G29-E29)/G29) -> 0.94096605 | I29: =(5*E29)/2 -> 129.6356 | J29: =(4*E29) -> 207.41696 | O29: K000953X13 | P29: 1384.5
A30: NEW | B30: 3/8” Emitter, 954 cavity foil, standard, stainless, 3/4” FPT, 1/4” FPT | D30: S003953033 | E30: 34.07794 | F30: 1447.5 | G30: =F30*$G$5 -> 535.575 | H30: =((G30-E30)/G30) -> 0.9363713 | I30: =(5*E30)/2 -> 85.19485 | J30: =(4*E30) -> 136.31176 | O30: K000953X26 | P30: 1384.5
B31: 1/2" Emitters | I31: =(5*E31)/2 -> 0 | J31: =(4*E31) -> 0 | O31: K000953X53 | P31: 1384.5
B32: 1/2” Emitter, 953 dome foil, standard, stainless, 3/4” MPT, 1/4” FPT | C32: 1 | D32: S006953X40 | E32: 27.14865 | F32: 1565 | G32: =F32*$G$5 -> 579.05 | H32: =((G32-E32)/G32) -> 0.95311519 | I32: =(5*E32)/2 -> 67.871625 | J32: =(4*E32) -> 108.5946 | K32: Yes | O32: K000953X79 | P32: 1384.5
B33: 1/2” Emitter, 953 dome foil, standard, brass, 3/4” MPT, 1/4” FPT | C33: 1 | D33: S006953400 | E33: 102.34866 | F33: 1123.5 | G33: =F33*$G$5 -> 415.695 | H33: =((G33-E33)/G33) -> 0.75378905 | I33: =(5*E33)/2 -> 255.87165 | J33: =(4*E33) -> 409.39464 | O33: K000953013 | P33: 1165.5
B34: 1/2” Emitter, 953 dome foil, escutcheon, stainless 3/4” FPT, 1/4” FPT | C34: 1 | D34: S00495350A | E34: 142.6213 | F34: 3383 | G34: =F34*$G$5 -> 1251.71 | H34: =((G34-E34)/G34) -> 0.88605883 | I34: =(5*E34)/2 -> 356.55325 | J34: =(4*E34) -> 570.4852 | K34: Yes | O34: K000953026 | P34: 1165.5
B35: 1/2” Emitter, 953 dome foil, standard, PVDF, 3/4” MPT, 1/4” FPT | C35: 1 | D35: S006953406 | E35: 230.5925 | F35: 2086.5 | G35: =F35*$G$5 -> 772.005 | H35: =((G35-E35)/G35) -> 0.70130699 | I35: =(5*E35)/2 -> 576.48125 | J35: =(4*E35) -> 922.37 | O35: K000953053 | P35: 1165.5
A36: NEW | B36: 1/2” Emitter, 953 dome foil, escutcheon, stainless, 3/4” FPT, 1/4” FPT | D36: S004953511 | E36: 60.22476 | H36: =((G36-E36)/G36) -> #DIV/0! | I36: =(5*E36)/2 -> 150.5619 | J36: =(4*E36) -> 240.89904 | O36: K000953079 | P36: 1165.5
A37: NEW | B37: 1/2” Emitter, 953 dome foil, standard, stainless, 3/4” FPT, 1/4” FPT | D37: S004953513 | E37: 35.2038 | H37: =((G37-E37)/G37) -> #DIV/0! | I37: =(5*E37)/2 -> 88.0095 | J37: =(4*E37) -> 140.8152 | O37: K000953106 | P37: 1165.5
B38: 5/8" Emitters | I38: =(5*E38)/2 -> 0 | J38: =(4*E38) -> 0 | O38: P000950001 | P38: 9.5
B39: 5/8” Emitter, 953 dome foil, standard, stainless, 3/4” MPT, 1/4” FPT | C39: 1 | D39: S006953X50 | E39: 93.35758 | F39: 1936.5 | G39: =F39*$G$5 -> 716.505 | H39: =((G39-E39)/G39) -> 0.86970422 | I39: =(5*E39)/2 -> 233.39395 | J39: =(4*E39) -> 373.43032 | K39: Yes | O39: P000950018 | P39: 18.5
